{
 "cells": [
  {
   "cell_type": "code",
   "execution_count": 1,
   "metadata": {},
   "outputs": [
    {
     "name": "stderr",
     "output_type": "stream",
     "text": [
      "C:\\Users\\ghdak\\anaconda3\\envs\\dl\\lib\\site-packages\\ipykernel_launcher.py:33: SettingWithCopyWarning: \n",
      "A value is trying to be set on a copy of a slice from a DataFrame\n",
      "\n",
      "See the caveats in the documentation: https://pandas.pydata.org/pandas-docs/stable/user_guide/indexing.html#returning-a-view-versus-a-copy\n",
      "C:\\Users\\ghdak\\anaconda3\\envs\\dl\\lib\\site-packages\\ipykernel_launcher.py:35: SettingWithCopyWarning: \n",
      "A value is trying to be set on a copy of a slice from a DataFrame\n",
      "\n",
      "See the caveats in the documentation: https://pandas.pydata.org/pandas-docs/stable/user_guide/indexing.html#returning-a-view-versus-a-copy\n",
      "C:\\Users\\ghdak\\anaconda3\\envs\\dl\\lib\\site-packages\\ipykernel_launcher.py:37: SettingWithCopyWarning: \n",
      "A value is trying to be set on a copy of a slice from a DataFrame\n",
      "\n",
      "See the caveats in the documentation: https://pandas.pydata.org/pandas-docs/stable/user_guide/indexing.html#returning-a-view-versus-a-copy\n",
      "C:\\Users\\ghdak\\anaconda3\\envs\\dl\\lib\\site-packages\\ipykernel_launcher.py:39: SettingWithCopyWarning: \n",
      "A value is trying to be set on a copy of a slice from a DataFrame\n",
      "\n",
      "See the caveats in the documentation: https://pandas.pydata.org/pandas-docs/stable/user_guide/indexing.html#returning-a-view-versus-a-copy\n",
      "C:\\Users\\ghdak\\anaconda3\\envs\\dl\\lib\\site-packages\\ipykernel_launcher.py:43: SettingWithCopyWarning: \n",
      "A value is trying to be set on a copy of a slice from a DataFrame\n",
      "\n",
      "See the caveats in the documentation: https://pandas.pydata.org/pandas-docs/stable/user_guide/indexing.html#returning-a-view-versus-a-copy\n",
      "C:\\Users\\ghdak\\anaconda3\\envs\\dl\\lib\\site-packages\\ipykernel_launcher.py:45: SettingWithCopyWarning: \n",
      "A value is trying to be set on a copy of a slice from a DataFrame\n",
      "\n",
      "See the caveats in the documentation: https://pandas.pydata.org/pandas-docs/stable/user_guide/indexing.html#returning-a-view-versus-a-copy\n",
      "C:\\Users\\ghdak\\anaconda3\\envs\\dl\\lib\\site-packages\\ipykernel_launcher.py:49: SettingWithCopyWarning: \n",
      "A value is trying to be set on a copy of a slice from a DataFrame\n",
      "\n",
      "See the caveats in the documentation: https://pandas.pydata.org/pandas-docs/stable/user_guide/indexing.html#returning-a-view-versus-a-copy\n",
      "C:\\Users\\ghdak\\anaconda3\\envs\\dl\\lib\\site-packages\\ipykernel_launcher.py:51: SettingWithCopyWarning: \n",
      "A value is trying to be set on a copy of a slice from a DataFrame\n",
      "\n",
      "See the caveats in the documentation: https://pandas.pydata.org/pandas-docs/stable/user_guide/indexing.html#returning-a-view-versus-a-copy\n"
     ]
    }
   ],
   "source": [
    "import numpy as np\n",
    "import pandas as pd\n",
    "import requests\n",
    "from pykrx import stock\n",
    "import time\n",
    "from datetime import datetime\n",
    "\n",
    "import matplotlib.pyplot as plt\n",
    "import matplotlib\n",
    "from matplotlib import font_manager, rc\n",
    "import platform\n",
    "if platform.system() == 'Windows':\n",
    "# 윈도우인 경우\n",
    "    font_name = font_manager.FontProperties(fname=\"c:/Windows/Fonts/malgun.ttf\").get_name()\n",
    "    rc('font', family=font_name)\n",
    "matplotlib.rcParams['axes.unicode_minus'] = False\n",
    "stock_list = pd.DataFrame({'종목코드':stock.get_market_ticker_list(market=\"ALL\")})\n",
    "stock_list['종목명'] = stock_list['종목코드'].map(lambda x: stock.get_market_ticker_name(x))\n",
    "\n",
    "stock_list = pd.DataFrame({'종목코드':stock.get_market_ticker_list(market=\"ALL\")})\n",
    "stock_list['종목명'] = stock_list['종목코드'].map(lambda x: stock.get_market_ticker_name(x))\n",
    "\n",
    "name = '카카오'\n",
    "fromdate = str(20180101)\n",
    "todate = str(20211104)\n",
    "\n",
    "ticker1 = stock_list.loc[stock_list['종목명']== name, '종목코드']\n",
    "df1 = stock.get_market_ohlcv_by_date(fromdate=fromdate, todate=todate, ticker=ticker1)\n",
    "\n",
    "seri = df1['종가']\n",
    "df = pd.DataFrame(seri, columns=['종가','일계도','이계도','일계도부호','이계도부호'])\n",
    "\n",
    "df['일계도'][0] = 0\n",
    "for i in range(1, len(seri)):\n",
    "    df['일계도'][i] = df['종가'][i] - df['종가'][i-1]\n",
    "\n",
    "df['이계도'][0] = 0\n",
    "for i in range(1, len(seri)):\n",
    "    df['이계도'][i] = df['일계도'][i] - df['일계도'][i-1]\n",
    "\n",
    "for i in range(len(df)):\n",
    "    if df['일계도'][i] >= 0:\n",
    "        df['일계도부호'][i] = 1\n",
    "    else:\n",
    "        df['일계도부호'][i] = 0\n",
    "\n",
    "for i in range(len(df)):\n",
    "    if df['이계도'][i] >= 0:\n",
    "        df['이계도부호'][i] = 1\n",
    "    else:\n",
    "        df['이계도부호'][i] = 0\n",
    "\n",
    "df_diff2 = df['일계도부호']\n",
    "df_diff2 = np.array(df_diff2)"
   ]
  },
  {
   "cell_type": "code",
   "execution_count": 6,
   "metadata": {},
   "outputs": [],
   "source": [
    "train_X = np.array([df_diff2[i:i+30] for i in range(len(df_diff2[:700]))])\n",
    "train_Y = np.array([df_diff2[i+31] for i in range(len(df_diff2[:700]))])"
   ]
  },
  {
   "cell_type": "code",
   "execution_count": 7,
   "metadata": {},
   "outputs": [],
   "source": [
    "test_X = np.array([df_diff2[i:i+30] for i in range(len(df_diff2[700:880]))])\n",
    "test_Y = np.array([df_diff2[i+31] for i in range(len(df_diff2[700:880]))])"
   ]
  },
  {
   "cell_type": "code",
   "execution_count": 8,
   "metadata": {},
   "outputs": [],
   "source": [
    "train_Y = train_Y.reshape(700,1)\n",
    "test_Y = test_Y.reshape(180,1)"
   ]
  },
  {
   "cell_type": "code",
   "execution_count": 19,
   "metadata": {},
   "outputs": [
    {
     "data": {
      "text/plain": [
       "((700, 30), (700, 1))"
      ]
     },
     "execution_count": 19,
     "metadata": {},
     "output_type": "execute_result"
    }
   ],
   "source": [
    "train_X.shape, train_Y.shape"
   ]
  },
  {
   "cell_type": "code",
   "execution_count": 10,
   "metadata": {},
   "outputs": [],
   "source": [
    "train_X = train_X.reshape(train_X.shape[0], 30, 1)\n",
    "test_X = test_X.reshape(test_X.shape[0], 30, 1)"
   ]
  },
  {
   "cell_type": "code",
   "execution_count": 11,
   "metadata": {},
   "outputs": [
    {
     "name": "stdout",
     "output_type": "stream",
     "text": [
      "Model: \"sequential\"\n",
      "_________________________________________________________________\n",
      "Layer (type)                 Output Shape              Param #   \n",
      "=================================================================\n",
      "lstm (LSTM)                  (None, 20)                1760      \n",
      "_________________________________________________________________\n",
      "dense (Dense)                (None, 1)                 21        \n",
      "=================================================================\n",
      "Total params: 1,781\n",
      "Trainable params: 1,781\n",
      "Non-trainable params: 0\n",
      "_________________________________________________________________\n"
     ]
    }
   ],
   "source": [
    "from tensorflow.keras.layers import LSTM \n",
    "from tensorflow.keras.models import Sequential \n",
    "from tensorflow.keras.layers import Dense \n",
    "import tensorflow.keras.backend as K \n",
    "from tensorflow.keras.callbacks import EarlyStopping\n",
    "\n",
    "K.clear_session()\n",
    "    \n",
    "model = Sequential() # Sequeatial Model \n",
    "model.add(LSTM(20, input_shape=(30, 1))) # (timestep, feature) \n",
    "model.add(Dense(1)) # output = 1 \n",
    "model.compile(loss='mean_squared_error', optimizer='adam') \n",
    "model.summary()\n"
   ]
  },
  {
   "cell_type": "code",
   "execution_count": 12,
   "metadata": {},
   "outputs": [
    {
     "name": "stderr",
     "output_type": "stream",
     "text": [
      "ERROR:root:Internal Python error in the inspect module.\n",
      "Below is the traceback from this internal error.\n",
      "\n",
      "ERROR:root:Internal Python error in the inspect module.\n",
      "Below is the traceback from this internal error.\n",
      "\n",
      "ERROR:root:Internal Python error in the inspect module.\n",
      "Below is the traceback from this internal error.\n",
      "\n"
     ]
    },
    {
     "name": "stdout",
     "output_type": "stream",
     "text": [
      "Traceback (most recent call last):\n",
      "  File \"C:\\Users\\ghdak\\anaconda3\\envs\\dl\\lib\\site-packages\\IPython\\core\\interactiveshell.py\", line 3444, in run_code\n",
      "    exec(code_obj, self.user_global_ns, self.user_ns)\n",
      "  File \"C:\\Users\\ghdak\\AppData\\Local\\Temp/ipykernel_8604/3955987928.py\", line 4, in <module>\n",
      "    batch_size=30, verbose=1, callbacks=[early_stop])\n",
      "  File \"C:\\Users\\ghdak\\anaconda3\\envs\\dl\\lib\\site-packages\\tensorflow_core\\python\\keras\\engine\\training.py\", line 728, in fit\n",
      "    use_multiprocessing=use_multiprocessing)\n",
      "  File \"C:\\Users\\ghdak\\anaconda3\\envs\\dl\\lib\\site-packages\\tensorflow_core\\python\\keras\\engine\\training_v2.py\", line 224, in fit\n",
      "    distribution_strategy=strategy)\n",
      "  File \"C:\\Users\\ghdak\\anaconda3\\envs\\dl\\lib\\site-packages\\tensorflow_core\\python\\keras\\engine\\training_v2.py\", line 547, in _process_training_inputs\n",
      "    use_multiprocessing=use_multiprocessing)\n",
      "  File \"C:\\Users\\ghdak\\anaconda3\\envs\\dl\\lib\\site-packages\\tensorflow_core\\python\\keras\\engine\\training_v2.py\", line 606, in _process_inputs\n",
      "    use_multiprocessing=use_multiprocessing)\n",
      "  File \"C:\\Users\\ghdak\\anaconda3\\envs\\dl\\lib\\site-packages\\tensorflow_core\\python\\keras\\engine\\data_adapter.py\", line 321, in __init__\n",
      "    dataset_ops.DatasetV2.from_tensors(inputs).repeat()\n",
      "  File \"C:\\Users\\ghdak\\anaconda3\\envs\\dl\\lib\\site-packages\\tensorflow_core\\python\\data\\ops\\dataset_ops.py\", line 414, in from_tensors\n",
      "    return TensorDataset(tensors)\n",
      "  File \"C:\\Users\\ghdak\\anaconda3\\envs\\dl\\lib\\site-packages\\tensorflow_core\\python\\data\\ops\\dataset_ops.py\", line 2335, in __init__\n",
      "    element = structure.normalize_element(element)\n",
      "  File \"C:\\Users\\ghdak\\anaconda3\\envs\\dl\\lib\\site-packages\\tensorflow_core\\python\\data\\util\\structure.py\", line 111, in normalize_element\n",
      "    ops.convert_to_tensor(t, name=\"component_%d\" % i))\n",
      "  File \"C:\\Users\\ghdak\\anaconda3\\envs\\dl\\lib\\site-packages\\tensorflow_core\\python\\framework\\ops.py\", line 1184, in convert_to_tensor\n",
      "    return convert_to_tensor_v2(value, dtype, preferred_dtype, name)\n",
      "  File \"C:\\Users\\ghdak\\anaconda3\\envs\\dl\\lib\\site-packages\\tensorflow_core\\python\\framework\\ops.py\", line 1242, in convert_to_tensor_v2\n",
      "    as_ref=False)\n",
      "  File \"C:\\Users\\ghdak\\anaconda3\\envs\\dl\\lib\\site-packages\\tensorflow_core\\python\\framework\\ops.py\", line 1296, in internal_convert_to_tensor\n",
      "    ret = conversion_func(value, dtype=dtype, name=name, as_ref=as_ref)\n",
      "  File \"C:\\Users\\ghdak\\anaconda3\\envs\\dl\\lib\\site-packages\\tensorflow_core\\python\\framework\\tensor_conversion_registry.py\", line 52, in _default_conversion_function\n",
      "    return constant_op.constant(value, dtype, name=name)\n",
      "  File \"C:\\Users\\ghdak\\anaconda3\\envs\\dl\\lib\\site-packages\\tensorflow_core\\python\\framework\\constant_op.py\", line 227, in constant\n",
      "    allow_broadcast=True)\n",
      "  File \"C:\\Users\\ghdak\\anaconda3\\envs\\dl\\lib\\site-packages\\tensorflow_core\\python\\framework\\constant_op.py\", line 235, in _constant_impl\n",
      "    t = convert_to_eager_tensor(value, ctx, dtype)\n",
      "  File \"C:\\Users\\ghdak\\anaconda3\\envs\\dl\\lib\\site-packages\\tensorflow_core\\python\\framework\\constant_op.py\", line 96, in convert_to_eager_tensor\n",
      "    return ops.EagerTensor(value, ctx.device_name, dtype)\n",
      "ValueError: Failed to convert a NumPy array to a Tensor (Unsupported object type int).\n",
      "\n",
      "During handling of the above exception, another exception occurred:\n",
      "\n",
      "Traceback (most recent call last):\n",
      "  File \"C:\\Users\\ghdak\\anaconda3\\envs\\dl\\lib\\site-packages\\IPython\\core\\interactiveshell.py\", line 2064, in showtraceback\n",
      "    stb = value._render_traceback_()\n",
      "AttributeError: 'ValueError' object has no attribute '_render_traceback_'\n",
      "\n",
      "During handling of the above exception, another exception occurred:\n",
      "\n",
      "Traceback (most recent call last):\n",
      "  File \"C:\\Users\\ghdak\\anaconda3\\envs\\dl\\lib\\site-packages\\IPython\\core\\ultratb.py\", line 1101, in get_records\n",
      "    return _fixed_getinnerframes(etb, number_of_lines_of_context, tb_offset)\n",
      "  File \"C:\\Users\\ghdak\\anaconda3\\envs\\dl\\lib\\site-packages\\IPython\\core\\ultratb.py\", line 248, in wrapped\n",
      "    return f(*args, **kwargs)\n",
      "  File \"C:\\Users\\ghdak\\anaconda3\\envs\\dl\\lib\\site-packages\\IPython\\core\\ultratb.py\", line 281, in _fixed_getinnerframes\n",
      "    records = fix_frame_records_filenames(inspect.getinnerframes(etb, context))\n",
      "  File \"C:\\Users\\ghdak\\anaconda3\\envs\\dl\\lib\\inspect.py\", line 1502, in getinnerframes\n",
      "    frameinfo = (tb.tb_frame,) + getframeinfo(tb, context)\n",
      "  File \"C:\\Users\\ghdak\\anaconda3\\envs\\dl\\lib\\inspect.py\", line 1460, in getframeinfo\n",
      "    filename = getsourcefile(frame) or getfile(frame)\n",
      "  File \"C:\\Users\\ghdak\\anaconda3\\envs\\dl\\lib\\inspect.py\", line 696, in getsourcefile\n",
      "    if getattr(getmodule(object, filename), '__loader__', None) is not None:\n",
      "  File \"C:\\Users\\ghdak\\anaconda3\\envs\\dl\\lib\\inspect.py\", line 733, in getmodule\n",
      "    if ismodule(module) and hasattr(module, '__file__'):\n",
      "  File \"C:\\Users\\ghdak\\anaconda3\\envs\\dl\\lib\\site-packages\\tensorflow\\__init__.py\", line 50, in __getattr__\n",
      "    module = self._load()\n",
      "  File \"C:\\Users\\ghdak\\anaconda3\\envs\\dl\\lib\\site-packages\\tensorflow\\__init__.py\", line 44, in _load\n",
      "    module = _importlib.import_module(self.__name__)\n",
      "  File \"C:\\Users\\ghdak\\anaconda3\\envs\\dl\\lib\\importlib\\__init__.py\", line 127, in import_module\n",
      "    return _bootstrap._gcd_import(name[level:], package, level)\n",
      "  File \"<frozen importlib._bootstrap>\", line 1006, in _gcd_import\n",
      "  File \"<frozen importlib._bootstrap>\", line 983, in _find_and_load\n",
      "  File \"<frozen importlib._bootstrap>\", line 965, in _find_and_load_unlocked\n",
      "ModuleNotFoundError: No module named 'tensorflow_core.estimator'\n",
      "Traceback (most recent call last):\n",
      "  File \"C:\\Users\\ghdak\\anaconda3\\envs\\dl\\lib\\site-packages\\IPython\\core\\interactiveshell.py\", line 3444, in run_code\n",
      "    exec(code_obj, self.user_global_ns, self.user_ns)\n",
      "  File \"C:\\Users\\ghdak\\AppData\\Local\\Temp/ipykernel_8604/3955987928.py\", line 4, in <module>\n",
      "    batch_size=30, verbose=1, callbacks=[early_stop])\n",
      "  File \"C:\\Users\\ghdak\\anaconda3\\envs\\dl\\lib\\site-packages\\tensorflow_core\\python\\keras\\engine\\training.py\", line 728, in fit\n",
      "    use_multiprocessing=use_multiprocessing)\n",
      "  File \"C:\\Users\\ghdak\\anaconda3\\envs\\dl\\lib\\site-packages\\tensorflow_core\\python\\keras\\engine\\training_v2.py\", line 224, in fit\n",
      "    distribution_strategy=strategy)\n",
      "  File \"C:\\Users\\ghdak\\anaconda3\\envs\\dl\\lib\\site-packages\\tensorflow_core\\python\\keras\\engine\\training_v2.py\", line 547, in _process_training_inputs\n",
      "    use_multiprocessing=use_multiprocessing)\n",
      "  File \"C:\\Users\\ghdak\\anaconda3\\envs\\dl\\lib\\site-packages\\tensorflow_core\\python\\keras\\engine\\training_v2.py\", line 606, in _process_inputs\n",
      "    use_multiprocessing=use_multiprocessing)\n",
      "  File \"C:\\Users\\ghdak\\anaconda3\\envs\\dl\\lib\\site-packages\\tensorflow_core\\python\\keras\\engine\\data_adapter.py\", line 321, in __init__\n",
      "    dataset_ops.DatasetV2.from_tensors(inputs).repeat()\n",
      "  File \"C:\\Users\\ghdak\\anaconda3\\envs\\dl\\lib\\site-packages\\tensorflow_core\\python\\data\\ops\\dataset_ops.py\", line 414, in from_tensors\n",
      "    return TensorDataset(tensors)\n",
      "  File \"C:\\Users\\ghdak\\anaconda3\\envs\\dl\\lib\\site-packages\\tensorflow_core\\python\\data\\ops\\dataset_ops.py\", line 2335, in __init__\n",
      "    element = structure.normalize_element(element)\n",
      "  File \"C:\\Users\\ghdak\\anaconda3\\envs\\dl\\lib\\site-packages\\tensorflow_core\\python\\data\\util\\structure.py\", line 111, in normalize_element\n",
      "    ops.convert_to_tensor(t, name=\"component_%d\" % i))\n",
      "  File \"C:\\Users\\ghdak\\anaconda3\\envs\\dl\\lib\\site-packages\\tensorflow_core\\python\\framework\\ops.py\", line 1184, in convert_to_tensor\n",
      "    return convert_to_tensor_v2(value, dtype, preferred_dtype, name)\n",
      "  File \"C:\\Users\\ghdak\\anaconda3\\envs\\dl\\lib\\site-packages\\tensorflow_core\\python\\framework\\ops.py\", line 1242, in convert_to_tensor_v2\n",
      "    as_ref=False)\n",
      "  File \"C:\\Users\\ghdak\\anaconda3\\envs\\dl\\lib\\site-packages\\tensorflow_core\\python\\framework\\ops.py\", line 1296, in internal_convert_to_tensor\n",
      "    ret = conversion_func(value, dtype=dtype, name=name, as_ref=as_ref)\n",
      "  File \"C:\\Users\\ghdak\\anaconda3\\envs\\dl\\lib\\site-packages\\tensorflow_core\\python\\framework\\tensor_conversion_registry.py\", line 52, in _default_conversion_function\n",
      "    return constant_op.constant(value, dtype, name=name)\n",
      "  File \"C:\\Users\\ghdak\\anaconda3\\envs\\dl\\lib\\site-packages\\tensorflow_core\\python\\framework\\constant_op.py\", line 227, in constant\n",
      "    allow_broadcast=True)\n",
      "  File \"C:\\Users\\ghdak\\anaconda3\\envs\\dl\\lib\\site-packages\\tensorflow_core\\python\\framework\\constant_op.py\", line 235, in _constant_impl\n",
      "    t = convert_to_eager_tensor(value, ctx, dtype)\n",
      "  File \"C:\\Users\\ghdak\\anaconda3\\envs\\dl\\lib\\site-packages\\tensorflow_core\\python\\framework\\constant_op.py\", line 96, in convert_to_eager_tensor\n",
      "    return ops.EagerTensor(value, ctx.device_name, dtype)\n",
      "ValueError: Failed to convert a NumPy array to a Tensor (Unsupported object type int).\n",
      "\n",
      "During handling of the above exception, another exception occurred:\n",
      "\n",
      "Traceback (most recent call last):\n",
      "  File \"C:\\Users\\ghdak\\anaconda3\\envs\\dl\\lib\\site-packages\\IPython\\core\\interactiveshell.py\", line 2064, in showtraceback\n",
      "    stb = value._render_traceback_()\n",
      "AttributeError: 'ValueError' object has no attribute '_render_traceback_'\n",
      "\n",
      "During handling of the above exception, another exception occurred:\n",
      "\n",
      "Traceback (most recent call last):\n",
      "  File \"C:\\Users\\ghdak\\anaconda3\\envs\\dl\\lib\\site-packages\\IPython\\core\\interactiveshell.py\", line 3364, in run_ast_nodes\n",
      "    if (await self.run_code(code, result,  async_=asy)):\n",
      "  File \"C:\\Users\\ghdak\\anaconda3\\envs\\dl\\lib\\site-packages\\IPython\\core\\interactiveshell.py\", line 3461, in run_code\n",
      "    self.showtraceback(running_compiled_code=True)\n",
      "  File \"C:\\Users\\ghdak\\anaconda3\\envs\\dl\\lib\\site-packages\\IPython\\core\\interactiveshell.py\", line 2067, in showtraceback\n",
      "    value, tb, tb_offset=tb_offset)\n",
      "  File \"C:\\Users\\ghdak\\anaconda3\\envs\\dl\\lib\\site-packages\\IPython\\core\\ultratb.py\", line 1368, in structured_traceback\n",
      "    self, etype, value, tb, tb_offset, number_of_lines_of_context)\n",
      "  File \"C:\\Users\\ghdak\\anaconda3\\envs\\dl\\lib\\site-packages\\IPython\\core\\ultratb.py\", line 1268, in structured_traceback\n",
      "    self, etype, value, tb, tb_offset, number_of_lines_of_context\n",
      "  File \"C:\\Users\\ghdak\\anaconda3\\envs\\dl\\lib\\site-packages\\IPython\\core\\ultratb.py\", line 1125, in structured_traceback\n",
      "    tb_offset)\n",
      "  File \"C:\\Users\\ghdak\\anaconda3\\envs\\dl\\lib\\site-packages\\IPython\\core\\ultratb.py\", line 1082, in format_exception_as_a_whole\n",
      "    last_unique, recursion_repeat = find_recursion(orig_etype, evalue, records)\n",
      "  File \"C:\\Users\\ghdak\\anaconda3\\envs\\dl\\lib\\site-packages\\IPython\\core\\ultratb.py\", line 382, in find_recursion\n",
      "    return len(records), 0\n",
      "TypeError: object of type 'NoneType' has no len()\n",
      "\n",
      "During handling of the above exception, another exception occurred:\n",
      "\n",
      "Traceback (most recent call last):\n",
      "  File \"C:\\Users\\ghdak\\anaconda3\\envs\\dl\\lib\\site-packages\\IPython\\core\\interactiveshell.py\", line 2064, in showtraceback\n",
      "    stb = value._render_traceback_()\n",
      "AttributeError: 'TypeError' object has no attribute '_render_traceback_'\n",
      "\n",
      "During handling of the above exception, another exception occurred:\n",
      "\n",
      "Traceback (most recent call last):\n",
      "  File \"C:\\Users\\ghdak\\anaconda3\\envs\\dl\\lib\\site-packages\\IPython\\core\\ultratb.py\", line 1101, in get_records\n",
      "    return _fixed_getinnerframes(etb, number_of_lines_of_context, tb_offset)\n",
      "  File \"C:\\Users\\ghdak\\anaconda3\\envs\\dl\\lib\\site-packages\\IPython\\core\\ultratb.py\", line 248, in wrapped\n",
      "    return f(*args, **kwargs)\n",
      "  File \"C:\\Users\\ghdak\\anaconda3\\envs\\dl\\lib\\site-packages\\IPython\\core\\ultratb.py\", line 281, in _fixed_getinnerframes\n",
      "    records = fix_frame_records_filenames(inspect.getinnerframes(etb, context))\n",
      "  File \"C:\\Users\\ghdak\\anaconda3\\envs\\dl\\lib\\inspect.py\", line 1502, in getinnerframes\n",
      "    frameinfo = (tb.tb_frame,) + getframeinfo(tb, context)\n",
      "  File \"C:\\Users\\ghdak\\anaconda3\\envs\\dl\\lib\\inspect.py\", line 1460, in getframeinfo\n",
      "    filename = getsourcefile(frame) or getfile(frame)\n",
      "  File \"C:\\Users\\ghdak\\anaconda3\\envs\\dl\\lib\\inspect.py\", line 696, in getsourcefile\n",
      "    if getattr(getmodule(object, filename), '__loader__', None) is not None:\n",
      "  File \"C:\\Users\\ghdak\\anaconda3\\envs\\dl\\lib\\inspect.py\", line 733, in getmodule\n",
      "    if ismodule(module) and hasattr(module, '__file__'):\n",
      "  File \"C:\\Users\\ghdak\\anaconda3\\envs\\dl\\lib\\site-packages\\tensorflow\\__init__.py\", line 50, in __getattr__\n",
      "    module = self._load()\n",
      "  File \"C:\\Users\\ghdak\\anaconda3\\envs\\dl\\lib\\site-packages\\tensorflow\\__init__.py\", line 44, in _load\n",
      "    module = _importlib.import_module(self.__name__)\n",
      "  File \"C:\\Users\\ghdak\\anaconda3\\envs\\dl\\lib\\importlib\\__init__.py\", line 127, in import_module\n",
      "    return _bootstrap._gcd_import(name[level:], package, level)\n",
      "  File \"<frozen importlib._bootstrap>\", line 1006, in _gcd_import\n",
      "  File \"<frozen importlib._bootstrap>\", line 983, in _find_and_load\n",
      "  File \"<frozen importlib._bootstrap>\", line 965, in _find_and_load_unlocked\n",
      "ModuleNotFoundError: No module named 'tensorflow_core.estimator'\n",
      "Traceback (most recent call last):\n",
      "  File \"C:\\Users\\ghdak\\anaconda3\\envs\\dl\\lib\\site-packages\\IPython\\core\\interactiveshell.py\", line 3444, in run_code\n",
      "    exec(code_obj, self.user_global_ns, self.user_ns)\n",
      "  File \"C:\\Users\\ghdak\\AppData\\Local\\Temp/ipykernel_8604/3955987928.py\", line 4, in <module>\n",
      "    batch_size=30, verbose=1, callbacks=[early_stop])\n",
      "  File \"C:\\Users\\ghdak\\anaconda3\\envs\\dl\\lib\\site-packages\\tensorflow_core\\python\\keras\\engine\\training.py\", line 728, in fit\n",
      "    use_multiprocessing=use_multiprocessing)\n",
      "  File \"C:\\Users\\ghdak\\anaconda3\\envs\\dl\\lib\\site-packages\\tensorflow_core\\python\\keras\\engine\\training_v2.py\", line 224, in fit\n",
      "    distribution_strategy=strategy)\n",
      "  File \"C:\\Users\\ghdak\\anaconda3\\envs\\dl\\lib\\site-packages\\tensorflow_core\\python\\keras\\engine\\training_v2.py\", line 547, in _process_training_inputs\n",
      "    use_multiprocessing=use_multiprocessing)\n",
      "  File \"C:\\Users\\ghdak\\anaconda3\\envs\\dl\\lib\\site-packages\\tensorflow_core\\python\\keras\\engine\\training_v2.py\", line 606, in _process_inputs\n",
      "    use_multiprocessing=use_multiprocessing)\n",
      "  File \"C:\\Users\\ghdak\\anaconda3\\envs\\dl\\lib\\site-packages\\tensorflow_core\\python\\keras\\engine\\data_adapter.py\", line 321, in __init__\n",
      "    dataset_ops.DatasetV2.from_tensors(inputs).repeat()\n",
      "  File \"C:\\Users\\ghdak\\anaconda3\\envs\\dl\\lib\\site-packages\\tensorflow_core\\python\\data\\ops\\dataset_ops.py\", line 414, in from_tensors\n",
      "    return TensorDataset(tensors)\n",
      "  File \"C:\\Users\\ghdak\\anaconda3\\envs\\dl\\lib\\site-packages\\tensorflow_core\\python\\data\\ops\\dataset_ops.py\", line 2335, in __init__\n",
      "    element = structure.normalize_element(element)\n",
      "  File \"C:\\Users\\ghdak\\anaconda3\\envs\\dl\\lib\\site-packages\\tensorflow_core\\python\\data\\util\\structure.py\", line 111, in normalize_element\n",
      "    ops.convert_to_tensor(t, name=\"component_%d\" % i))\n",
      "  File \"C:\\Users\\ghdak\\anaconda3\\envs\\dl\\lib\\site-packages\\tensorflow_core\\python\\framework\\ops.py\", line 1184, in convert_to_tensor\n",
      "    return convert_to_tensor_v2(value, dtype, preferred_dtype, name)\n",
      "  File \"C:\\Users\\ghdak\\anaconda3\\envs\\dl\\lib\\site-packages\\tensorflow_core\\python\\framework\\ops.py\", line 1242, in convert_to_tensor_v2\n",
      "    as_ref=False)\n",
      "  File \"C:\\Users\\ghdak\\anaconda3\\envs\\dl\\lib\\site-packages\\tensorflow_core\\python\\framework\\ops.py\", line 1296, in internal_convert_to_tensor\n",
      "    ret = conversion_func(value, dtype=dtype, name=name, as_ref=as_ref)\n",
      "  File \"C:\\Users\\ghdak\\anaconda3\\envs\\dl\\lib\\site-packages\\tensorflow_core\\python\\framework\\tensor_conversion_registry.py\", line 52, in _default_conversion_function\n",
      "    return constant_op.constant(value, dtype, name=name)\n",
      "  File \"C:\\Users\\ghdak\\anaconda3\\envs\\dl\\lib\\site-packages\\tensorflow_core\\python\\framework\\constant_op.py\", line 227, in constant\n",
      "    allow_broadcast=True)\n",
      "  File \"C:\\Users\\ghdak\\anaconda3\\envs\\dl\\lib\\site-packages\\tensorflow_core\\python\\framework\\constant_op.py\", line 235, in _constant_impl\n",
      "    t = convert_to_eager_tensor(value, ctx, dtype)\n",
      "  File \"C:\\Users\\ghdak\\anaconda3\\envs\\dl\\lib\\site-packages\\tensorflow_core\\python\\framework\\constant_op.py\", line 96, in convert_to_eager_tensor\n",
      "    return ops.EagerTensor(value, ctx.device_name, dtype)\n",
      "ValueError: Failed to convert a NumPy array to a Tensor (Unsupported object type int).\n",
      "\n",
      "During handling of the above exception, another exception occurred:\n",
      "\n",
      "Traceback (most recent call last):\n",
      "  File \"C:\\Users\\ghdak\\anaconda3\\envs\\dl\\lib\\site-packages\\IPython\\core\\interactiveshell.py\", line 2064, in showtraceback\n",
      "    stb = value._render_traceback_()\n",
      "AttributeError: 'ValueError' object has no attribute '_render_traceback_'\n",
      "\n",
      "During handling of the above exception, another exception occurred:\n",
      "\n",
      "Traceback (most recent call last):\n",
      "  File \"C:\\Users\\ghdak\\anaconda3\\envs\\dl\\lib\\site-packages\\IPython\\core\\interactiveshell.py\", line 3364, in run_ast_nodes\n",
      "    if (await self.run_code(code, result,  async_=asy)):\n",
      "  File \"C:\\Users\\ghdak\\anaconda3\\envs\\dl\\lib\\site-packages\\IPython\\core\\interactiveshell.py\", line 3461, in run_code\n",
      "    self.showtraceback(running_compiled_code=True)\n",
      "  File \"C:\\Users\\ghdak\\anaconda3\\envs\\dl\\lib\\site-packages\\IPython\\core\\interactiveshell.py\", line 2067, in showtraceback\n",
      "    value, tb, tb_offset=tb_offset)\n",
      "  File \"C:\\Users\\ghdak\\anaconda3\\envs\\dl\\lib\\site-packages\\IPython\\core\\ultratb.py\", line 1368, in structured_traceback\n",
      "    self, etype, value, tb, tb_offset, number_of_lines_of_context)\n",
      "  File \"C:\\Users\\ghdak\\anaconda3\\envs\\dl\\lib\\site-packages\\IPython\\core\\ultratb.py\", line 1268, in structured_traceback\n",
      "    self, etype, value, tb, tb_offset, number_of_lines_of_context\n",
      "  File \"C:\\Users\\ghdak\\anaconda3\\envs\\dl\\lib\\site-packages\\IPython\\core\\ultratb.py\", line 1125, in structured_traceback\n",
      "    tb_offset)\n",
      "  File \"C:\\Users\\ghdak\\anaconda3\\envs\\dl\\lib\\site-packages\\IPython\\core\\ultratb.py\", line 1082, in format_exception_as_a_whole\n",
      "    last_unique, recursion_repeat = find_recursion(orig_etype, evalue, records)\n",
      "  File \"C:\\Users\\ghdak\\anaconda3\\envs\\dl\\lib\\site-packages\\IPython\\core\\ultratb.py\", line 382, in find_recursion\n",
      "    return len(records), 0\n",
      "TypeError: object of type 'NoneType' has no len()\n",
      "\n",
      "During handling of the above exception, another exception occurred:\n",
      "\n",
      "Traceback (most recent call last):\n",
      "  File \"C:\\Users\\ghdak\\anaconda3\\envs\\dl\\lib\\site-packages\\IPython\\core\\interactiveshell.py\", line 2064, in showtraceback\n",
      "    stb = value._render_traceback_()\n",
      "AttributeError: 'TypeError' object has no attribute '_render_traceback_'\n",
      "\n",
      "During handling of the above exception, another exception occurred:\n",
      "\n",
      "Traceback (most recent call last):\n",
      "  File \"C:\\Users\\ghdak\\anaconda3\\envs\\dl\\lib\\site-packages\\IPython\\core\\interactiveshell.py\", line 2947, in _run_cell\n",
      "    return runner(coro)\n",
      "  File \"C:\\Users\\ghdak\\anaconda3\\envs\\dl\\lib\\site-packages\\IPython\\core\\async_helpers.py\", line 68, in _pseudo_sync_runner\n",
      "    coro.send(None)\n",
      "  File \"C:\\Users\\ghdak\\anaconda3\\envs\\dl\\lib\\site-packages\\IPython\\core\\interactiveshell.py\", line 3173, in run_cell_async\n",
      "    interactivity=interactivity, compiler=compiler, result=result)\n",
      "  File \"C:\\Users\\ghdak\\anaconda3\\envs\\dl\\lib\\site-packages\\IPython\\core\\interactiveshell.py\", line 3383, in run_ast_nodes\n",
      "    self.showtraceback()\n",
      "  File \"C:\\Users\\ghdak\\anaconda3\\envs\\dl\\lib\\site-packages\\IPython\\core\\interactiveshell.py\", line 2067, in showtraceback\n",
      "    value, tb, tb_offset=tb_offset)\n",
      "  File \"C:\\Users\\ghdak\\anaconda3\\envs\\dl\\lib\\site-packages\\IPython\\core\\ultratb.py\", line 1368, in structured_traceback\n",
      "    self, etype, value, tb, tb_offset, number_of_lines_of_context)\n",
      "  File \"C:\\Users\\ghdak\\anaconda3\\envs\\dl\\lib\\site-packages\\IPython\\core\\ultratb.py\", line 1268, in structured_traceback\n",
      "    self, etype, value, tb, tb_offset, number_of_lines_of_context\n",
      "  File \"C:\\Users\\ghdak\\anaconda3\\envs\\dl\\lib\\site-packages\\IPython\\core\\ultratb.py\", line 1143, in structured_traceback\n",
      "    chained_exceptions_tb_offset)\n",
      "  File \"C:\\Users\\ghdak\\anaconda3\\envs\\dl\\lib\\site-packages\\IPython\\core\\ultratb.py\", line 1082, in format_exception_as_a_whole\n",
      "    last_unique, recursion_repeat = find_recursion(orig_etype, evalue, records)\n",
      "  File \"C:\\Users\\ghdak\\anaconda3\\envs\\dl\\lib\\site-packages\\IPython\\core\\ultratb.py\", line 382, in find_recursion\n",
      "    return len(records), 0\n",
      "TypeError: object of type 'NoneType' has no len()\n",
      "\n",
      "During handling of the above exception, another exception occurred:\n",
      "\n",
      "Traceback (most recent call last):\n",
      "  File \"C:\\Users\\ghdak\\anaconda3\\envs\\dl\\lib\\site-packages\\IPython\\core\\interactiveshell.py\", line 2064, in showtraceback\n",
      "    stb = value._render_traceback_()\n",
      "AttributeError: 'TypeError' object has no attribute '_render_traceback_'\n",
      "\n",
      "During handling of the above exception, another exception occurred:\n",
      "\n",
      "Traceback (most recent call last):\n",
      "  File \"C:\\Users\\ghdak\\anaconda3\\envs\\dl\\lib\\site-packages\\IPython\\core\\ultratb.py\", line 1101, in get_records\n",
      "    return _fixed_getinnerframes(etb, number_of_lines_of_context, tb_offset)\n",
      "  File \"C:\\Users\\ghdak\\anaconda3\\envs\\dl\\lib\\site-packages\\IPython\\core\\ultratb.py\", line 248, in wrapped\n",
      "    return f(*args, **kwargs)\n",
      "  File \"C:\\Users\\ghdak\\anaconda3\\envs\\dl\\lib\\site-packages\\IPython\\core\\ultratb.py\", line 281, in _fixed_getinnerframes\n",
      "    records = fix_frame_records_filenames(inspect.getinnerframes(etb, context))\n",
      "  File \"C:\\Users\\ghdak\\anaconda3\\envs\\dl\\lib\\inspect.py\", line 1502, in getinnerframes\n",
      "    frameinfo = (tb.tb_frame,) + getframeinfo(tb, context)\n",
      "  File \"C:\\Users\\ghdak\\anaconda3\\envs\\dl\\lib\\inspect.py\", line 1460, in getframeinfo\n",
      "    filename = getsourcefile(frame) or getfile(frame)\n",
      "  File \"C:\\Users\\ghdak\\anaconda3\\envs\\dl\\lib\\inspect.py\", line 696, in getsourcefile\n",
      "    if getattr(getmodule(object, filename), '__loader__', None) is not None:\n",
      "  File \"C:\\Users\\ghdak\\anaconda3\\envs\\dl\\lib\\inspect.py\", line 733, in getmodule\n",
      "    if ismodule(module) and hasattr(module, '__file__'):\n",
      "  File \"C:\\Users\\ghdak\\anaconda3\\envs\\dl\\lib\\site-packages\\tensorflow\\__init__.py\", line 50, in __getattr__\n",
      "    module = self._load()\n",
      "  File \"C:\\Users\\ghdak\\anaconda3\\envs\\dl\\lib\\site-packages\\tensorflow\\__init__.py\", line 44, in _load\n",
      "    module = _importlib.import_module(self.__name__)\n",
      "  File \"C:\\Users\\ghdak\\anaconda3\\envs\\dl\\lib\\importlib\\__init__.py\", line 127, in import_module\n",
      "    return _bootstrap._gcd_import(name[level:], package, level)\n",
      "  File \"<frozen importlib._bootstrap>\", line 1006, in _gcd_import\n",
      "  File \"<frozen importlib._bootstrap>\", line 983, in _find_and_load\n",
      "  File \"<frozen importlib._bootstrap>\", line 965, in _find_and_load_unlocked\n",
      "ModuleNotFoundError: No module named 'tensorflow_core.estimator'\n"
     ]
    }
   ],
   "source": [
    "early_stop = EarlyStopping(monitor='loss', patience=1, verbose=1)\n",
    "\n",
    "model.fit(train_X, train_Y, epochs=100,\n",
    "          batch_size=30, verbose=1, callbacks=[early_stop])"
   ]
  },
  {
   "cell_type": "code",
   "execution_count": null,
   "metadata": {},
   "outputs": [],
   "source": []
  },
  {
   "cell_type": "code",
   "execution_count": 32,
   "metadata": {},
   "outputs": [],
   "source": [
    "import import_ipynb\n",
    "from momentum import model"
   ]
  },
  {
   "cell_type": "code",
   "execution_count": 33,
   "metadata": {},
   "outputs": [
    {
     "name": "stderr",
     "output_type": "stream",
     "text": [
      "C:\\Users\\ghdak\\anaconda3\\envs\\gpu_env\\lib\\site-packages\\sklearn\\base.py:561: FutureWarning: Arrays of bytes/strings is being converted to decimal numbers if dtype='numeric'. This behavior is deprecated in 0.24 and will be removed in 1.1 (renaming of 0.26). Please convert your data to numeric values explicitly instead.\n",
      "  X = check_array(X, **check_params)\n"
     ]
    },
    {
     "data": {
      "text/plain": [
       "array([ 0.26768783,  0.41374824,  0.22665378,  0.43345531,  0.31884867,\n",
       "        0.38649868,  0.62158501,  0.8373333 ,  0.47945128,  0.95364879,\n",
       "        0.41451476,  0.43648125,  0.6847098 ,  0.48067746,  0.88978416,\n",
       "        0.42086582,  0.50391141,  0.6474081 ,  0.24804938,  0.32638992,\n",
       "        0.585119  ,  0.7596226 ,  0.62993814,  0.38199133,  0.48475597,\n",
       "        0.48088229,  0.28453316,  0.33873695,  0.46849417,  0.64547477,\n",
       "        0.74703992,  0.48587066,  0.63989393,  0.43683798,  0.61284096,\n",
       "        0.67160984,  0.85008405,  0.94525221,  0.47485962,  0.64192948,\n",
       "        0.36555496,  0.66839314,  0.27696661,  0.49880123,  0.71271825,\n",
       "        0.7559414 ,  0.57747873,  0.37218869,  0.30207655,  0.51623011,\n",
       "        0.53503195,  0.35026355,  0.41952344,  0.33251302,  0.28733416,\n",
       "        0.53990351,  0.41698558,  0.76757478,  0.59796604,  0.73865361,\n",
       "        0.96011338,  0.83639161,  0.63678196,  0.66694729,  0.3670489 ,\n",
       "        0.30605897,  0.3164337 ,  0.31982371,  0.14811374,  0.3718164 ,\n",
       "        0.45286387,  0.46095941,  0.35971102,  0.29926473,  0.70430906,\n",
       "        0.62196072,  0.44960776,  0.66358171,  0.65339336,  0.40793322,\n",
       "        0.41418564,  0.53389697,  0.87050188,  0.89928422,  0.42844724,\n",
       "        0.89391795,  0.77458078,  0.60864403,  0.40661655,  0.3634852 ,\n",
       "        0.32970834,  0.25912836,  0.23966365,  0.3159079 ,  0.51675158,\n",
       "        0.22273731,  0.41752108,  0.80108955,  0.78779442,  1.16002141,\n",
       "        0.83243605,  0.6831058 ,  0.68426057,  0.40120509,  0.48705697,\n",
       "        0.59815845,  0.36382823,  0.58456946,  0.16019416,  0.31299995,\n",
       "        0.50889135,  0.49770924,  0.81007172,  0.69344185,  0.70805421,\n",
       "        0.53917241,  0.64201204,  0.45025348,  0.40627966,  0.64427357,\n",
       "        0.42306401,  0.62091235,  0.29257006,  0.12523381,  0.54961792,\n",
       "        0.50185091,  0.7982899 ,  0.53206413,  0.54603415,  0.57927608,\n",
       "        0.63472008,  0.5852261 ,  0.69689411,  0.59814169,  0.83856072,\n",
       "        0.56794384,  0.69229834,  0.54088396,  0.32149386,  0.35888443,\n",
       "        0.46779045,  0.36599303,  0.41746142, -0.02035033,  0.19051611,\n",
       "        0.5385923 ,  0.36619723,  0.40052273,  0.63776583,  0.95818496])"
      ]
     },
     "execution_count": 33,
     "metadata": {},
     "output_type": "execute_result"
    }
   ],
   "source": [
    "pred_y = model.predict(test_x)\n",
    "pred_y"
   ]
  },
  {
   "cell_type": "code",
   "execution_count": 36,
   "metadata": {},
   "outputs": [],
   "source": [
    "trans_pred = pred_y.copy()\n",
    "for i in range(len(pred_y)):\n",
    "    if pred_y[i] < 0.5:\n",
    "        trans_pred[i] = 0\n",
    "    else:\n",
    "        trans_pred[i] = 1"
   ]
  },
  {
   "cell_type": "code",
   "execution_count": 37,
   "metadata": {},
   "outputs": [
    {
     "data": {
      "text/plain": [
       "0.42"
      ]
     },
     "execution_count": 37,
     "metadata": {},
     "output_type": "execute_result"
    }
   ],
   "source": [
    "from sklearn.metrics import mean_absolute_error\n",
    "\n",
    "mae = mean_absolute_error(test_y, trans_pred)\n",
    "round(mae, 2)"
   ]
  },
  {
   "cell_type": "code",
   "execution_count": null,
   "metadata": {},
   "outputs": [],
   "source": []
  }
 ],
 "metadata": {
  "interpreter": {
   "hash": "18858f7dd6518bd0da41b16ef5d2ecbfc918b23a137a85ac817008ae9b185217"
  },
  "kernelspec": {
   "display_name": "Python 3.7.11 64-bit ('dl': conda)",
   "name": "python3"
  },
  "language_info": {
   "codemirror_mode": {
    "name": "ipython",
    "version": 3
   },
   "file_extension": ".py",
   "mimetype": "text/x-python",
   "name": "python",
   "nbconvert_exporter": "python",
   "pygments_lexer": "ipython3",
   "version": "3.7.11"
  },
  "orig_nbformat": 4
 },
 "nbformat": 4,
 "nbformat_minor": 2
}
